{
 "cells": [
  {
   "cell_type": "code",
   "execution_count": null,
   "id": "e607bf87",
   "metadata": {},
   "outputs": [],
   "source": [
    "from tensorflow.keras.preprocessing.image import ImageDataGenerator\n",
    "from tensorflow.keras.models import Sequential\n",
    "from tensorflow.keras.layers import Conv2D, MaxPooling2D, Flatten, Dense, Dropout\n",
    "from tensorflow.keras.optimizers import Adam"
   ]
  },
  {
   "cell_type": "code",
   "execution_count": null,
   "id": "488511fb",
   "metadata": {},
   "outputs": [],
   "source": [
    "# Definir la ruta de la base de datos\n",
    "database_path = '../../database/105_classes_pins_dataset/'"
   ]
  },
  {
   "cell_type": "code",
   "execution_count": null,
   "id": "b20d3b55",
   "metadata": {},
   "outputs": [],
   "source": [
    "# Preprocesamiento de datos con ImageDataGenerator\n",
    "train_datagen = ImageDataGenerator(rescale=1./255,\n",
    "                                   shear_range=0.2,\n",
    "                                   zoom_range=0.2,\n",
    "                                   horizontal_flip=True,\n",
    "                                   validation_split=0.2)"
   ]
  },
  {
   "cell_type": "code",
   "execution_count": null,
   "id": "2b8dd134",
   "metadata": {},
   "outputs": [],
   "source": [
    "# Generadores de datos para entrenamiento y validación\n",
    "train_generator = train_datagen.flow_from_directory(\n",
    "    database_path,\n",
    "    target_size=(224, 224),\n",
    "    batch_size=32,\n",
    "    class_mode='categorical',\n",
    "    subset='training')\n",
    "validation_generator = train_datagen.flow_from_directory(\n",
    "    database_path,\n",
    "    target_size=(224, 224),\n",
    "    batch_size=32,\n",
    "    class_mode='categorical',\n",
    "    subset='validation')"
   ]
  },
  {
   "cell_type": "code",
   "execution_count": null,
   "id": "62a149a2",
   "metadata": {},
   "outputs": [],
   "source": [
    "# Inicializar el modelo\n",
    "model = Sequential()"
   ]
  },
  {
   "cell_type": "code",
   "execution_count": null,
   "id": "571dcebf",
   "metadata": {},
   "outputs": [],
   "source": [
    "# Agregar capas convolucionales y de pooling\n",
    "model.add(Conv2D(32, (3, 3), activation='relu', input_shape=(224, 224, 3)))\n",
    "model.add(MaxPooling2D((2, 2)))"
   ]
  },
  {
   "cell_type": "code",
   "execution_count": null,
   "id": "29f0eb56",
   "metadata": {},
   "outputs": [],
   "source": [
    "# Agregar capas fully connected\n",
    "model.add(Flatten())\n",
    "model.add(Dense(128, activation='relu'))\n",
    "model.add(Dropout(0.5))\n",
    "model.add(Dense(len(train_generator.class_indices), activation='softmax'))  # Número de clases\n"
   ]
  },
  {
   "cell_type": "code",
   "execution_count": null,
   "id": "592f4aa6",
   "metadata": {},
   "outputs": [],
   "source": [
    "# Compilar el modelo\n",
    "model.compile(optimizer=Adam(learning_rate=0.1),\n",
    "              loss='categorical_crossentropy',\n",
    "              metrics=['accuracy'])\n"
   ]
  },
  {
   "cell_type": "code",
   "execution_count": null,
   "id": "576db93c",
   "metadata": {},
   "outputs": [],
   "source": [
    "# Entrenar el modelo\n",
    "model.fit(train_generator,\n",
    "          steps_per_epoch=len(train_generator),\n",
    "          epochs=10,\n",
    "          validation_data=validation_generator,\n",
    "          validation_steps=len(validation_generator))"
   ]
  },
  {
   "cell_type": "code",
   "execution_count": null,
   "id": "b6d9078f",
   "metadata": {},
   "outputs": [
    {
     "name": "stderr",
     "output_type": "stream",
     "text": [
      "ERROR:root:Internal Python error in the inspect module.\n",
      "Below is the traceback from this internal error.\n",
      "\n",
      "ERROR:root:Internal Python error in the inspect module.\n",
      "Below is the traceback from this internal error.\n",
      "\n",
      "ERROR:root:Internal Python error in the inspect module.\n",
      "Below is the traceback from this internal error.\n",
      "\n"
     ]
    },
    {
     "name": "stdout",
     "output_type": "stream",
     "text": [
      "Traceback (most recent call last):\n",
      "  File \"C:\\Users\\Familia\\anaconda3\\envs\\entornoGPU\\lib\\site-packages\\IPython\\core\\interactiveshell.py\", line 3457, in run_code\n",
      "    exec(code_obj, self.user_global_ns, self.user_ns)\n",
      "  File \"C:\\Users\\Familia\\AppData\\Local\\Temp\\ipykernel_14276\\4158939425.py\", line 6, in <module>\n",
      "    tf.config.experimental.set_visible_devices(gpus[1], 'GPU')\n",
      "IndexError: list index out of range\n",
      "\n",
      "During handling of the above exception, another exception occurred:\n",
      "\n",
      "Traceback (most recent call last):\n",
      "  File \"C:\\Users\\Familia\\anaconda3\\envs\\entornoGPU\\lib\\site-packages\\IPython\\core\\interactiveshell.py\", line 2077, in showtraceback\n",
      "    stb = value._render_traceback_()\n",
      "AttributeError: 'IndexError' object has no attribute '_render_traceback_'\n",
      "\n",
      "During handling of the above exception, another exception occurred:\n",
      "\n",
      "Traceback (most recent call last):\n",
      "  File \"C:\\Users\\Familia\\anaconda3\\envs\\entornoGPU\\lib\\site-packages\\IPython\\core\\ultratb.py\", line 1101, in get_records\n",
      "    return _fixed_getinnerframes(etb, number_of_lines_of_context, tb_offset)\n",
      "  File \"C:\\Users\\Familia\\anaconda3\\envs\\entornoGPU\\lib\\site-packages\\IPython\\core\\ultratb.py\", line 248, in wrapped\n",
      "    return f(*args, **kwargs)\n",
      "  File \"C:\\Users\\Familia\\anaconda3\\envs\\entornoGPU\\lib\\site-packages\\IPython\\core\\ultratb.py\", line 281, in _fixed_getinnerframes\n",
      "    records = fix_frame_records_filenames(inspect.getinnerframes(etb, context))\n",
      "  File \"C:\\Users\\Familia\\anaconda3\\envs\\entornoGPU\\lib\\inspect.py\", line 1502, in getinnerframes\n",
      "    frameinfo = (tb.tb_frame,) + getframeinfo(tb, context)\n",
      "  File \"C:\\Users\\Familia\\anaconda3\\envs\\entornoGPU\\lib\\inspect.py\", line 1460, in getframeinfo\n",
      "    filename = getsourcefile(frame) or getfile(frame)\n",
      "  File \"C:\\Users\\Familia\\anaconda3\\envs\\entornoGPU\\lib\\inspect.py\", line 696, in getsourcefile\n",
      "    if getattr(getmodule(object, filename), '__loader__', None) is not None:\n",
      "  File \"C:\\Users\\Familia\\anaconda3\\envs\\entornoGPU\\lib\\inspect.py\", line 733, in getmodule\n",
      "    if ismodule(module) and hasattr(module, '__file__'):\n",
      "  File \"C:\\Users\\Familia\\anaconda3\\envs\\entornoGPU\\lib\\site-packages\\tensorflow\\__init__.py\", line 50, in __getattr__\n",
      "    module = self._load()\n",
      "  File \"C:\\Users\\Familia\\anaconda3\\envs\\entornoGPU\\lib\\site-packages\\tensorflow\\__init__.py\", line 44, in _load\n",
      "    module = _importlib.import_module(self.__name__)\n",
      "  File \"C:\\Users\\Familia\\anaconda3\\envs\\entornoGPU\\lib\\importlib\\__init__.py\", line 127, in import_module\n",
      "    return _bootstrap._gcd_import(name[level:], package, level)\n",
      "  File \"<frozen importlib._bootstrap>\", line 1006, in _gcd_import\n",
      "  File \"<frozen importlib._bootstrap>\", line 983, in _find_and_load\n",
      "  File \"<frozen importlib._bootstrap>\", line 965, in _find_and_load_unlocked\n",
      "ModuleNotFoundError: No module named 'tensorflow_core.estimator'\n",
      "ERROR! Session/line number was not unique in database. History logging moved to new session 206\n",
      "Traceback (most recent call last):\n",
      "  File \"C:\\Users\\Familia\\anaconda3\\envs\\entornoGPU\\lib\\site-packages\\IPython\\core\\interactiveshell.py\", line 3457, in run_code\n",
      "    exec(code_obj, self.user_global_ns, self.user_ns)\n",
      "  File \"C:\\Users\\Familia\\AppData\\Local\\Temp\\ipykernel_14276\\4158939425.py\", line 6, in <module>\n",
      "    tf.config.experimental.set_visible_devices(gpus[1], 'GPU')\n",
      "IndexError: list index out of range\n",
      "\n",
      "During handling of the above exception, another exception occurred:\n",
      "\n",
      "Traceback (most recent call last):\n",
      "  File \"C:\\Users\\Familia\\anaconda3\\envs\\entornoGPU\\lib\\site-packages\\IPython\\core\\interactiveshell.py\", line 2077, in showtraceback\n",
      "    stb = value._render_traceback_()\n",
      "AttributeError: 'IndexError' object has no attribute '_render_traceback_'\n",
      "\n",
      "During handling of the above exception, another exception occurred:\n",
      "\n",
      "Traceback (most recent call last):\n",
      "  File \"C:\\Users\\Familia\\anaconda3\\envs\\entornoGPU\\lib\\site-packages\\IPython\\core\\interactiveshell.py\", line 3377, in run_ast_nodes\n",
      "    if (await self.run_code(code, result,  async_=asy)):\n",
      "  File \"C:\\Users\\Familia\\anaconda3\\envs\\entornoGPU\\lib\\site-packages\\IPython\\core\\interactiveshell.py\", line 3474, in run_code\n",
      "    self.showtraceback(running_compiled_code=True)\n",
      "  File \"C:\\Users\\Familia\\anaconda3\\envs\\entornoGPU\\lib\\site-packages\\IPython\\core\\interactiveshell.py\", line 2080, in showtraceback\n",
      "    value, tb, tb_offset=tb_offset)\n",
      "  File \"C:\\Users\\Familia\\anaconda3\\envs\\entornoGPU\\lib\\site-packages\\IPython\\core\\ultratb.py\", line 1368, in structured_traceback\n",
      "    self, etype, value, tb, tb_offset, number_of_lines_of_context)\n",
      "  File \"C:\\Users\\Familia\\anaconda3\\envs\\entornoGPU\\lib\\site-packages\\IPython\\core\\ultratb.py\", line 1268, in structured_traceback\n",
      "    self, etype, value, tb, tb_offset, number_of_lines_of_context\n",
      "  File \"C:\\Users\\Familia\\anaconda3\\envs\\entornoGPU\\lib\\site-packages\\IPython\\core\\ultratb.py\", line 1125, in structured_traceback\n",
      "    tb_offset)\n",
      "  File \"C:\\Users\\Familia\\anaconda3\\envs\\entornoGPU\\lib\\site-packages\\IPython\\core\\ultratb.py\", line 1082, in format_exception_as_a_whole\n",
      "    last_unique, recursion_repeat = find_recursion(orig_etype, evalue, records)\n",
      "  File \"C:\\Users\\Familia\\anaconda3\\envs\\entornoGPU\\lib\\site-packages\\IPython\\core\\ultratb.py\", line 382, in find_recursion\n",
      "    return len(records), 0\n",
      "TypeError: object of type 'NoneType' has no len()\n",
      "\n",
      "During handling of the above exception, another exception occurred:\n",
      "\n",
      "Traceback (most recent call last):\n",
      "  File \"C:\\Users\\Familia\\anaconda3\\envs\\entornoGPU\\lib\\site-packages\\IPython\\core\\interactiveshell.py\", line 2077, in showtraceback\n",
      "    stb = value._render_traceback_()\n",
      "AttributeError: 'TypeError' object has no attribute '_render_traceback_'\n",
      "\n",
      "During handling of the above exception, another exception occurred:\n",
      "\n",
      "Traceback (most recent call last):\n",
      "  File \"C:\\Users\\Familia\\anaconda3\\envs\\entornoGPU\\lib\\site-packages\\IPython\\core\\ultratb.py\", line 1101, in get_records\n",
      "    return _fixed_getinnerframes(etb, number_of_lines_of_context, tb_offset)\n",
      "  File \"C:\\Users\\Familia\\anaconda3\\envs\\entornoGPU\\lib\\site-packages\\IPython\\core\\ultratb.py\", line 248, in wrapped\n",
      "    return f(*args, **kwargs)\n",
      "  File \"C:\\Users\\Familia\\anaconda3\\envs\\entornoGPU\\lib\\site-packages\\IPython\\core\\ultratb.py\", line 281, in _fixed_getinnerframes\n",
      "    records = fix_frame_records_filenames(inspect.getinnerframes(etb, context))\n",
      "  File \"C:\\Users\\Familia\\anaconda3\\envs\\entornoGPU\\lib\\inspect.py\", line 1502, in getinnerframes\n",
      "    frameinfo = (tb.tb_frame,) + getframeinfo(tb, context)\n",
      "  File \"C:\\Users\\Familia\\anaconda3\\envs\\entornoGPU\\lib\\inspect.py\", line 1460, in getframeinfo\n",
      "    filename = getsourcefile(frame) or getfile(frame)\n",
      "  File \"C:\\Users\\Familia\\anaconda3\\envs\\entornoGPU\\lib\\inspect.py\", line 696, in getsourcefile\n",
      "    if getattr(getmodule(object, filename), '__loader__', None) is not None:\n",
      "  File \"C:\\Users\\Familia\\anaconda3\\envs\\entornoGPU\\lib\\inspect.py\", line 733, in getmodule\n",
      "    if ismodule(module) and hasattr(module, '__file__'):\n",
      "  File \"C:\\Users\\Familia\\anaconda3\\envs\\entornoGPU\\lib\\site-packages\\tensorflow\\__init__.py\", line 50, in __getattr__\n",
      "    module = self._load()\n",
      "  File \"C:\\Users\\Familia\\anaconda3\\envs\\entornoGPU\\lib\\site-packages\\tensorflow\\__init__.py\", line 44, in _load\n",
      "    module = _importlib.import_module(self.__name__)\n",
      "  File \"C:\\Users\\Familia\\anaconda3\\envs\\entornoGPU\\lib\\importlib\\__init__.py\", line 127, in import_module\n",
      "    return _bootstrap._gcd_import(name[level:], package, level)\n",
      "  File \"<frozen importlib._bootstrap>\", line 1006, in _gcd_import\n",
      "  File \"<frozen importlib._bootstrap>\", line 983, in _find_and_load\n",
      "  File \"<frozen importlib._bootstrap>\", line 965, in _find_and_load_unlocked\n",
      "ModuleNotFoundError: No module named 'tensorflow_core.estimator'\n",
      "Traceback (most recent call last):\n",
      "  File \"C:\\Users\\Familia\\anaconda3\\envs\\entornoGPU\\lib\\site-packages\\IPython\\core\\interactiveshell.py\", line 3457, in run_code\n",
      "    exec(code_obj, self.user_global_ns, self.user_ns)\n",
      "  File \"C:\\Users\\Familia\\AppData\\Local\\Temp\\ipykernel_14276\\4158939425.py\", line 6, in <module>\n",
      "    tf.config.experimental.set_visible_devices(gpus[1], 'GPU')\n",
      "IndexError: list index out of range\n",
      "\n",
      "During handling of the above exception, another exception occurred:\n",
      "\n",
      "Traceback (most recent call last):\n",
      "  File \"C:\\Users\\Familia\\anaconda3\\envs\\entornoGPU\\lib\\site-packages\\IPython\\core\\interactiveshell.py\", line 2077, in showtraceback\n",
      "    stb = value._render_traceback_()\n",
      "AttributeError: 'IndexError' object has no attribute '_render_traceback_'\n",
      "\n",
      "During handling of the above exception, another exception occurred:\n",
      "\n",
      "Traceback (most recent call last):\n",
      "  File \"C:\\Users\\Familia\\anaconda3\\envs\\entornoGPU\\lib\\site-packages\\IPython\\core\\interactiveshell.py\", line 3377, in run_ast_nodes\n",
      "    if (await self.run_code(code, result,  async_=asy)):\n",
      "  File \"C:\\Users\\Familia\\anaconda3\\envs\\entornoGPU\\lib\\site-packages\\IPython\\core\\interactiveshell.py\", line 3474, in run_code\n",
      "    self.showtraceback(running_compiled_code=True)\n",
      "  File \"C:\\Users\\Familia\\anaconda3\\envs\\entornoGPU\\lib\\site-packages\\IPython\\core\\interactiveshell.py\", line 2080, in showtraceback\n",
      "    value, tb, tb_offset=tb_offset)\n",
      "  File \"C:\\Users\\Familia\\anaconda3\\envs\\entornoGPU\\lib\\site-packages\\IPython\\core\\ultratb.py\", line 1368, in structured_traceback\n",
      "    self, etype, value, tb, tb_offset, number_of_lines_of_context)\n",
      "  File \"C:\\Users\\Familia\\anaconda3\\envs\\entornoGPU\\lib\\site-packages\\IPython\\core\\ultratb.py\", line 1268, in structured_traceback\n",
      "    self, etype, value, tb, tb_offset, number_of_lines_of_context\n",
      "  File \"C:\\Users\\Familia\\anaconda3\\envs\\entornoGPU\\lib\\site-packages\\IPython\\core\\ultratb.py\", line 1125, in structured_traceback\n",
      "    tb_offset)\n",
      "  File \"C:\\Users\\Familia\\anaconda3\\envs\\entornoGPU\\lib\\site-packages\\IPython\\core\\ultratb.py\", line 1082, in format_exception_as_a_whole\n",
      "    last_unique, recursion_repeat = find_recursion(orig_etype, evalue, records)\n",
      "  File \"C:\\Users\\Familia\\anaconda3\\envs\\entornoGPU\\lib\\site-packages\\IPython\\core\\ultratb.py\", line 382, in find_recursion\n",
      "    return len(records), 0\n",
      "TypeError: object of type 'NoneType' has no len()\n",
      "\n",
      "During handling of the above exception, another exception occurred:\n",
      "\n",
      "Traceback (most recent call last):\n",
      "  File \"C:\\Users\\Familia\\anaconda3\\envs\\entornoGPU\\lib\\site-packages\\IPython\\core\\interactiveshell.py\", line 2077, in showtraceback\n",
      "    stb = value._render_traceback_()\n",
      "AttributeError: 'TypeError' object has no attribute '_render_traceback_'\n",
      "\n",
      "During handling of the above exception, another exception occurred:\n",
      "\n",
      "Traceback (most recent call last):\n",
      "  File \"C:\\Users\\Familia\\anaconda3\\envs\\entornoGPU\\lib\\site-packages\\IPython\\core\\interactiveshell.py\", line 2960, in _run_cell\n",
      "    return runner(coro)\n",
      "  File \"C:\\Users\\Familia\\anaconda3\\envs\\entornoGPU\\lib\\site-packages\\IPython\\core\\async_helpers.py\", line 78, in _pseudo_sync_runner\n",
      "    coro.send(None)\n",
      "  File \"C:\\Users\\Familia\\anaconda3\\envs\\entornoGPU\\lib\\site-packages\\IPython\\core\\interactiveshell.py\", line 3186, in run_cell_async\n",
      "    interactivity=interactivity, compiler=compiler, result=result)\n",
      "  File \"C:\\Users\\Familia\\anaconda3\\envs\\entornoGPU\\lib\\site-packages\\IPython\\core\\interactiveshell.py\", line 3396, in run_ast_nodes\n",
      "    self.showtraceback()\n",
      "  File \"C:\\Users\\Familia\\anaconda3\\envs\\entornoGPU\\lib\\site-packages\\IPython\\core\\interactiveshell.py\", line 2080, in showtraceback\n",
      "    value, tb, tb_offset=tb_offset)\n",
      "  File \"C:\\Users\\Familia\\anaconda3\\envs\\entornoGPU\\lib\\site-packages\\IPython\\core\\ultratb.py\", line 1368, in structured_traceback\n",
      "    self, etype, value, tb, tb_offset, number_of_lines_of_context)\n",
      "  File \"C:\\Users\\Familia\\anaconda3\\envs\\entornoGPU\\lib\\site-packages\\IPython\\core\\ultratb.py\", line 1268, in structured_traceback\n",
      "    self, etype, value, tb, tb_offset, number_of_lines_of_context\n",
      "  File \"C:\\Users\\Familia\\anaconda3\\envs\\entornoGPU\\lib\\site-packages\\IPython\\core\\ultratb.py\", line 1143, in structured_traceback\n",
      "    chained_exceptions_tb_offset)\n",
      "  File \"C:\\Users\\Familia\\anaconda3\\envs\\entornoGPU\\lib\\site-packages\\IPython\\core\\ultratb.py\", line 1082, in format_exception_as_a_whole\n",
      "    last_unique, recursion_repeat = find_recursion(orig_etype, evalue, records)\n",
      "  File \"C:\\Users\\Familia\\anaconda3\\envs\\entornoGPU\\lib\\site-packages\\IPython\\core\\ultratb.py\", line 382, in find_recursion\n",
      "    return len(records), 0\n",
      "TypeError: object of type 'NoneType' has no len()\n",
      "\n",
      "During handling of the above exception, another exception occurred:\n",
      "\n",
      "Traceback (most recent call last):\n",
      "  File \"C:\\Users\\Familia\\anaconda3\\envs\\entornoGPU\\lib\\site-packages\\IPython\\core\\interactiveshell.py\", line 2077, in showtraceback\n",
      "    stb = value._render_traceback_()\n",
      "AttributeError: 'TypeError' object has no attribute '_render_traceback_'\n",
      "\n",
      "During handling of the above exception, another exception occurred:\n",
      "\n",
      "Traceback (most recent call last):\n",
      "  File \"C:\\Users\\Familia\\anaconda3\\envs\\entornoGPU\\lib\\site-packages\\IPython\\core\\ultratb.py\", line 1101, in get_records\n",
      "    return _fixed_getinnerframes(etb, number_of_lines_of_context, tb_offset)\n",
      "  File \"C:\\Users\\Familia\\anaconda3\\envs\\entornoGPU\\lib\\site-packages\\IPython\\core\\ultratb.py\", line 248, in wrapped\n",
      "    return f(*args, **kwargs)\n",
      "  File \"C:\\Users\\Familia\\anaconda3\\envs\\entornoGPU\\lib\\site-packages\\IPython\\core\\ultratb.py\", line 281, in _fixed_getinnerframes\n",
      "    records = fix_frame_records_filenames(inspect.getinnerframes(etb, context))\n",
      "  File \"C:\\Users\\Familia\\anaconda3\\envs\\entornoGPU\\lib\\inspect.py\", line 1502, in getinnerframes\n",
      "    frameinfo = (tb.tb_frame,) + getframeinfo(tb, context)\n",
      "  File \"C:\\Users\\Familia\\anaconda3\\envs\\entornoGPU\\lib\\inspect.py\", line 1460, in getframeinfo\n",
      "    filename = getsourcefile(frame) or getfile(frame)\n",
      "  File \"C:\\Users\\Familia\\anaconda3\\envs\\entornoGPU\\lib\\inspect.py\", line 696, in getsourcefile\n",
      "    if getattr(getmodule(object, filename), '__loader__', None) is not None:\n",
      "  File \"C:\\Users\\Familia\\anaconda3\\envs\\entornoGPU\\lib\\inspect.py\", line 733, in getmodule\n",
      "    if ismodule(module) and hasattr(module, '__file__'):\n",
      "  File \"C:\\Users\\Familia\\anaconda3\\envs\\entornoGPU\\lib\\site-packages\\tensorflow\\__init__.py\", line 50, in __getattr__\n",
      "    module = self._load()\n",
      "  File \"C:\\Users\\Familia\\anaconda3\\envs\\entornoGPU\\lib\\site-packages\\tensorflow\\__init__.py\", line 44, in _load\n",
      "    module = _importlib.import_module(self.__name__)\n",
      "  File \"C:\\Users\\Familia\\anaconda3\\envs\\entornoGPU\\lib\\importlib\\__init__.py\", line 127, in import_module\n",
      "    return _bootstrap._gcd_import(name[level:], package, level)\n",
      "  File \"<frozen importlib._bootstrap>\", line 1006, in _gcd_import\n",
      "  File \"<frozen importlib._bootstrap>\", line 983, in _find_and_load\n",
      "  File \"<frozen importlib._bootstrap>\", line 965, in _find_and_load_unlocked\n",
      "ModuleNotFoundError: No module named 'tensorflow_core.estimator'\n"
     ]
    }
   ],
   "source": [
    "import tensorflow as tf\n",
    "\n",
    "gpus = tf.config.experimental.list_physical_devices('GPU')\n",
    "if gpus:\n",
    "    # Establecer visible_devices en la GPU 1\n",
    "    tf.config.experimental.set_visible_devices(gpus[1], 'GPU')\n",
    "    tf.config.experimental.set_memory_growth(gpus[1], True)  # Configurar crecimiento de memoria\n"
   ]
  },
  {
   "cell_type": "code",
   "execution_count": null,
   "id": "c353047c",
   "metadata": {},
   "outputs": [
    {
     "name": "stderr",
     "output_type": "stream",
     "text": [
      "ERROR:root:Internal Python error in the inspect module.\n",
      "Below is the traceback from this internal error.\n",
      "\n",
      "ERROR:root:Internal Python error in the inspect module.\n",
      "Below is the traceback from this internal error.\n",
      "\n",
      "ERROR:root:Internal Python error in the inspect module.\n",
      "Below is the traceback from this internal error.\n",
      "\n"
     ]
    },
    {
     "name": "stdout",
     "output_type": "stream",
     "text": [
      "Traceback (most recent call last):\n",
      "  File \"C:\\Users\\Familia\\anaconda3\\envs\\entornoGPU\\lib\\site-packages\\IPython\\core\\interactiveshell.py\", line 3457, in run_code\n",
      "    exec(code_obj, self.user_global_ns, self.user_ns)\n",
      "  File \"C:\\Users\\Familia\\AppData\\Local\\Temp\\ipykernel_14276\\3389381955.py\", line 5, in <module>\n",
      "    tf.config.experimental.set_visible_devices(physical_devices[1], 'GPU')\n",
      "IndexError: list index out of range\n",
      "\n",
      "During handling of the above exception, another exception occurred:\n",
      "\n",
      "Traceback (most recent call last):\n",
      "  File \"C:\\Users\\Familia\\anaconda3\\envs\\entornoGPU\\lib\\site-packages\\IPython\\core\\interactiveshell.py\", line 2077, in showtraceback\n",
      "    stb = value._render_traceback_()\n",
      "AttributeError: 'IndexError' object has no attribute '_render_traceback_'\n",
      "\n",
      "During handling of the above exception, another exception occurred:\n",
      "\n",
      "Traceback (most recent call last):\n",
      "  File \"C:\\Users\\Familia\\anaconda3\\envs\\entornoGPU\\lib\\site-packages\\IPython\\core\\ultratb.py\", line 1101, in get_records\n",
      "    return _fixed_getinnerframes(etb, number_of_lines_of_context, tb_offset)\n",
      "  File \"C:\\Users\\Familia\\anaconda3\\envs\\entornoGPU\\lib\\site-packages\\IPython\\core\\ultratb.py\", line 248, in wrapped\n",
      "    return f(*args, **kwargs)\n",
      "  File \"C:\\Users\\Familia\\anaconda3\\envs\\entornoGPU\\lib\\site-packages\\IPython\\core\\ultratb.py\", line 281, in _fixed_getinnerframes\n",
      "    records = fix_frame_records_filenames(inspect.getinnerframes(etb, context))\n",
      "  File \"C:\\Users\\Familia\\anaconda3\\envs\\entornoGPU\\lib\\inspect.py\", line 1502, in getinnerframes\n",
      "    frameinfo = (tb.tb_frame,) + getframeinfo(tb, context)\n",
      "  File \"C:\\Users\\Familia\\anaconda3\\envs\\entornoGPU\\lib\\inspect.py\", line 1460, in getframeinfo\n",
      "    filename = getsourcefile(frame) or getfile(frame)\n",
      "  File \"C:\\Users\\Familia\\anaconda3\\envs\\entornoGPU\\lib\\inspect.py\", line 696, in getsourcefile\n",
      "    if getattr(getmodule(object, filename), '__loader__', None) is not None:\n",
      "  File \"C:\\Users\\Familia\\anaconda3\\envs\\entornoGPU\\lib\\inspect.py\", line 733, in getmodule\n",
      "    if ismodule(module) and hasattr(module, '__file__'):\n",
      "  File \"C:\\Users\\Familia\\anaconda3\\envs\\entornoGPU\\lib\\site-packages\\tensorflow\\__init__.py\", line 50, in __getattr__\n",
      "    module = self._load()\n",
      "  File \"C:\\Users\\Familia\\anaconda3\\envs\\entornoGPU\\lib\\site-packages\\tensorflow\\__init__.py\", line 44, in _load\n",
      "    module = _importlib.import_module(self.__name__)\n",
      "  File \"C:\\Users\\Familia\\anaconda3\\envs\\entornoGPU\\lib\\importlib\\__init__.py\", line 127, in import_module\n",
      "    return _bootstrap._gcd_import(name[level:], package, level)\n",
      "  File \"<frozen importlib._bootstrap>\", line 1006, in _gcd_import\n",
      "  File \"<frozen importlib._bootstrap>\", line 983, in _find_and_load\n",
      "  File \"<frozen importlib._bootstrap>\", line 965, in _find_and_load_unlocked\n",
      "ModuleNotFoundError: No module named 'tensorflow_core.estimator'\n",
      "ERROR! Session/line number was not unique in database. History logging moved to new session 205\n",
      "Traceback (most recent call last):\n",
      "  File \"C:\\Users\\Familia\\anaconda3\\envs\\entornoGPU\\lib\\site-packages\\IPython\\core\\interactiveshell.py\", line 3457, in run_code\n",
      "    exec(code_obj, self.user_global_ns, self.user_ns)\n",
      "  File \"C:\\Users\\Familia\\AppData\\Local\\Temp\\ipykernel_14276\\3389381955.py\", line 5, in <module>\n",
      "    tf.config.experimental.set_visible_devices(physical_devices[1], 'GPU')\n",
      "IndexError: list index out of range\n",
      "\n",
      "During handling of the above exception, another exception occurred:\n",
      "\n",
      "Traceback (most recent call last):\n",
      "  File \"C:\\Users\\Familia\\anaconda3\\envs\\entornoGPU\\lib\\site-packages\\IPython\\core\\interactiveshell.py\", line 2077, in showtraceback\n",
      "    stb = value._render_traceback_()\n",
      "AttributeError: 'IndexError' object has no attribute '_render_traceback_'\n",
      "\n",
      "During handling of the above exception, another exception occurred:\n",
      "\n",
      "Traceback (most recent call last):\n",
      "  File \"C:\\Users\\Familia\\anaconda3\\envs\\entornoGPU\\lib\\site-packages\\IPython\\core\\interactiveshell.py\", line 3377, in run_ast_nodes\n",
      "    if (await self.run_code(code, result,  async_=asy)):\n",
      "  File \"C:\\Users\\Familia\\anaconda3\\envs\\entornoGPU\\lib\\site-packages\\IPython\\core\\interactiveshell.py\", line 3474, in run_code\n",
      "    self.showtraceback(running_compiled_code=True)\n",
      "  File \"C:\\Users\\Familia\\anaconda3\\envs\\entornoGPU\\lib\\site-packages\\IPython\\core\\interactiveshell.py\", line 2080, in showtraceback\n",
      "    value, tb, tb_offset=tb_offset)\n",
      "  File \"C:\\Users\\Familia\\anaconda3\\envs\\entornoGPU\\lib\\site-packages\\IPython\\core\\ultratb.py\", line 1368, in structured_traceback\n",
      "    self, etype, value, tb, tb_offset, number_of_lines_of_context)\n",
      "  File \"C:\\Users\\Familia\\anaconda3\\envs\\entornoGPU\\lib\\site-packages\\IPython\\core\\ultratb.py\", line 1268, in structured_traceback\n",
      "    self, etype, value, tb, tb_offset, number_of_lines_of_context\n",
      "  File \"C:\\Users\\Familia\\anaconda3\\envs\\entornoGPU\\lib\\site-packages\\IPython\\core\\ultratb.py\", line 1125, in structured_traceback\n",
      "    tb_offset)\n",
      "  File \"C:\\Users\\Familia\\anaconda3\\envs\\entornoGPU\\lib\\site-packages\\IPython\\core\\ultratb.py\", line 1082, in format_exception_as_a_whole\n",
      "    last_unique, recursion_repeat = find_recursion(orig_etype, evalue, records)\n",
      "  File \"C:\\Users\\Familia\\anaconda3\\envs\\entornoGPU\\lib\\site-packages\\IPython\\core\\ultratb.py\", line 382, in find_recursion\n",
      "    return len(records), 0\n",
      "TypeError: object of type 'NoneType' has no len()\n",
      "\n",
      "During handling of the above exception, another exception occurred:\n",
      "\n",
      "Traceback (most recent call last):\n",
      "  File \"C:\\Users\\Familia\\anaconda3\\envs\\entornoGPU\\lib\\site-packages\\IPython\\core\\interactiveshell.py\", line 2077, in showtraceback\n",
      "    stb = value._render_traceback_()\n",
      "AttributeError: 'TypeError' object has no attribute '_render_traceback_'\n",
      "\n",
      "During handling of the above exception, another exception occurred:\n",
      "\n",
      "Traceback (most recent call last):\n",
      "  File \"C:\\Users\\Familia\\anaconda3\\envs\\entornoGPU\\lib\\site-packages\\IPython\\core\\ultratb.py\", line 1101, in get_records\n",
      "    return _fixed_getinnerframes(etb, number_of_lines_of_context, tb_offset)\n",
      "  File \"C:\\Users\\Familia\\anaconda3\\envs\\entornoGPU\\lib\\site-packages\\IPython\\core\\ultratb.py\", line 248, in wrapped\n",
      "    return f(*args, **kwargs)\n",
      "  File \"C:\\Users\\Familia\\anaconda3\\envs\\entornoGPU\\lib\\site-packages\\IPython\\core\\ultratb.py\", line 281, in _fixed_getinnerframes\n",
      "    records = fix_frame_records_filenames(inspect.getinnerframes(etb, context))\n",
      "  File \"C:\\Users\\Familia\\anaconda3\\envs\\entornoGPU\\lib\\inspect.py\", line 1502, in getinnerframes\n",
      "    frameinfo = (tb.tb_frame,) + getframeinfo(tb, context)\n",
      "  File \"C:\\Users\\Familia\\anaconda3\\envs\\entornoGPU\\lib\\inspect.py\", line 1460, in getframeinfo\n",
      "    filename = getsourcefile(frame) or getfile(frame)\n",
      "  File \"C:\\Users\\Familia\\anaconda3\\envs\\entornoGPU\\lib\\inspect.py\", line 696, in getsourcefile\n",
      "    if getattr(getmodule(object, filename), '__loader__', None) is not None:\n",
      "  File \"C:\\Users\\Familia\\anaconda3\\envs\\entornoGPU\\lib\\inspect.py\", line 733, in getmodule\n",
      "    if ismodule(module) and hasattr(module, '__file__'):\n",
      "  File \"C:\\Users\\Familia\\anaconda3\\envs\\entornoGPU\\lib\\site-packages\\tensorflow\\__init__.py\", line 50, in __getattr__\n",
      "    module = self._load()\n",
      "  File \"C:\\Users\\Familia\\anaconda3\\envs\\entornoGPU\\lib\\site-packages\\tensorflow\\__init__.py\", line 44, in _load\n",
      "    module = _importlib.import_module(self.__name__)\n",
      "  File \"C:\\Users\\Familia\\anaconda3\\envs\\entornoGPU\\lib\\importlib\\__init__.py\", line 127, in import_module\n",
      "    return _bootstrap._gcd_import(name[level:], package, level)\n",
      "  File \"<frozen importlib._bootstrap>\", line 1006, in _gcd_import\n",
      "  File \"<frozen importlib._bootstrap>\", line 983, in _find_and_load\n",
      "  File \"<frozen importlib._bootstrap>\", line 965, in _find_and_load_unlocked\n",
      "ModuleNotFoundError: No module named 'tensorflow_core.estimator'\n",
      "Traceback (most recent call last):\n",
      "  File \"C:\\Users\\Familia\\anaconda3\\envs\\entornoGPU\\lib\\site-packages\\IPython\\core\\interactiveshell.py\", line 3457, in run_code\n",
      "    exec(code_obj, self.user_global_ns, self.user_ns)\n",
      "  File \"C:\\Users\\Familia\\AppData\\Local\\Temp\\ipykernel_14276\\3389381955.py\", line 5, in <module>\n",
      "    tf.config.experimental.set_visible_devices(physical_devices[1], 'GPU')\n",
      "IndexError: list index out of range\n",
      "\n",
      "During handling of the above exception, another exception occurred:\n",
      "\n",
      "Traceback (most recent call last):\n",
      "  File \"C:\\Users\\Familia\\anaconda3\\envs\\entornoGPU\\lib\\site-packages\\IPython\\core\\interactiveshell.py\", line 2077, in showtraceback\n",
      "    stb = value._render_traceback_()\n",
      "AttributeError: 'IndexError' object has no attribute '_render_traceback_'\n",
      "\n",
      "During handling of the above exception, another exception occurred:\n",
      "\n",
      "Traceback (most recent call last):\n",
      "  File \"C:\\Users\\Familia\\anaconda3\\envs\\entornoGPU\\lib\\site-packages\\IPython\\core\\interactiveshell.py\", line 3377, in run_ast_nodes\n",
      "    if (await self.run_code(code, result,  async_=asy)):\n",
      "  File \"C:\\Users\\Familia\\anaconda3\\envs\\entornoGPU\\lib\\site-packages\\IPython\\core\\interactiveshell.py\", line 3474, in run_code\n",
      "    self.showtraceback(running_compiled_code=True)\n",
      "  File \"C:\\Users\\Familia\\anaconda3\\envs\\entornoGPU\\lib\\site-packages\\IPython\\core\\interactiveshell.py\", line 2080, in showtraceback\n",
      "    value, tb, tb_offset=tb_offset)\n",
      "  File \"C:\\Users\\Familia\\anaconda3\\envs\\entornoGPU\\lib\\site-packages\\IPython\\core\\ultratb.py\", line 1368, in structured_traceback\n",
      "    self, etype, value, tb, tb_offset, number_of_lines_of_context)\n",
      "  File \"C:\\Users\\Familia\\anaconda3\\envs\\entornoGPU\\lib\\site-packages\\IPython\\core\\ultratb.py\", line 1268, in structured_traceback\n",
      "    self, etype, value, tb, tb_offset, number_of_lines_of_context\n",
      "  File \"C:\\Users\\Familia\\anaconda3\\envs\\entornoGPU\\lib\\site-packages\\IPython\\core\\ultratb.py\", line 1125, in structured_traceback\n",
      "    tb_offset)\n",
      "  File \"C:\\Users\\Familia\\anaconda3\\envs\\entornoGPU\\lib\\site-packages\\IPython\\core\\ultratb.py\", line 1082, in format_exception_as_a_whole\n",
      "    last_unique, recursion_repeat = find_recursion(orig_etype, evalue, records)\n",
      "  File \"C:\\Users\\Familia\\anaconda3\\envs\\entornoGPU\\lib\\site-packages\\IPython\\core\\ultratb.py\", line 382, in find_recursion\n",
      "    return len(records), 0\n",
      "TypeError: object of type 'NoneType' has no len()\n",
      "\n",
      "During handling of the above exception, another exception occurred:\n",
      "\n",
      "Traceback (most recent call last):\n",
      "  File \"C:\\Users\\Familia\\anaconda3\\envs\\entornoGPU\\lib\\site-packages\\IPython\\core\\interactiveshell.py\", line 2077, in showtraceback\n",
      "    stb = value._render_traceback_()\n",
      "AttributeError: 'TypeError' object has no attribute '_render_traceback_'\n",
      "\n",
      "During handling of the above exception, another exception occurred:\n",
      "\n",
      "Traceback (most recent call last):\n",
      "  File \"C:\\Users\\Familia\\anaconda3\\envs\\entornoGPU\\lib\\site-packages\\IPython\\core\\interactiveshell.py\", line 2960, in _run_cell\n",
      "    return runner(coro)\n",
      "  File \"C:\\Users\\Familia\\anaconda3\\envs\\entornoGPU\\lib\\site-packages\\IPython\\core\\async_helpers.py\", line 78, in _pseudo_sync_runner\n",
      "    coro.send(None)\n",
      "  File \"C:\\Users\\Familia\\anaconda3\\envs\\entornoGPU\\lib\\site-packages\\IPython\\core\\interactiveshell.py\", line 3186, in run_cell_async\n",
      "    interactivity=interactivity, compiler=compiler, result=result)\n",
      "  File \"C:\\Users\\Familia\\anaconda3\\envs\\entornoGPU\\lib\\site-packages\\IPython\\core\\interactiveshell.py\", line 3396, in run_ast_nodes\n",
      "    self.showtraceback()\n",
      "  File \"C:\\Users\\Familia\\anaconda3\\envs\\entornoGPU\\lib\\site-packages\\IPython\\core\\interactiveshell.py\", line 2080, in showtraceback\n",
      "    value, tb, tb_offset=tb_offset)\n",
      "  File \"C:\\Users\\Familia\\anaconda3\\envs\\entornoGPU\\lib\\site-packages\\IPython\\core\\ultratb.py\", line 1368, in structured_traceback\n",
      "    self, etype, value, tb, tb_offset, number_of_lines_of_context)\n",
      "  File \"C:\\Users\\Familia\\anaconda3\\envs\\entornoGPU\\lib\\site-packages\\IPython\\core\\ultratb.py\", line 1268, in structured_traceback\n",
      "    self, etype, value, tb, tb_offset, number_of_lines_of_context\n",
      "  File \"C:\\Users\\Familia\\anaconda3\\envs\\entornoGPU\\lib\\site-packages\\IPython\\core\\ultratb.py\", line 1143, in structured_traceback\n",
      "    chained_exceptions_tb_offset)\n",
      "  File \"C:\\Users\\Familia\\anaconda3\\envs\\entornoGPU\\lib\\site-packages\\IPython\\core\\ultratb.py\", line 1082, in format_exception_as_a_whole\n",
      "    last_unique, recursion_repeat = find_recursion(orig_etype, evalue, records)\n",
      "  File \"C:\\Users\\Familia\\anaconda3\\envs\\entornoGPU\\lib\\site-packages\\IPython\\core\\ultratb.py\", line 382, in find_recursion\n",
      "    return len(records), 0\n",
      "TypeError: object of type 'NoneType' has no len()\n",
      "\n",
      "During handling of the above exception, another exception occurred:\n",
      "\n",
      "Traceback (most recent call last):\n",
      "  File \"C:\\Users\\Familia\\anaconda3\\envs\\entornoGPU\\lib\\site-packages\\IPython\\core\\interactiveshell.py\", line 2077, in showtraceback\n",
      "    stb = value._render_traceback_()\n",
      "AttributeError: 'TypeError' object has no attribute '_render_traceback_'\n",
      "\n",
      "During handling of the above exception, another exception occurred:\n",
      "\n",
      "Traceback (most recent call last):\n",
      "  File \"C:\\Users\\Familia\\anaconda3\\envs\\entornoGPU\\lib\\site-packages\\IPython\\core\\ultratb.py\", line 1101, in get_records\n",
      "    return _fixed_getinnerframes(etb, number_of_lines_of_context, tb_offset)\n",
      "  File \"C:\\Users\\Familia\\anaconda3\\envs\\entornoGPU\\lib\\site-packages\\IPython\\core\\ultratb.py\", line 248, in wrapped\n",
      "    return f(*args, **kwargs)\n",
      "  File \"C:\\Users\\Familia\\anaconda3\\envs\\entornoGPU\\lib\\site-packages\\IPython\\core\\ultratb.py\", line 281, in _fixed_getinnerframes\n",
      "    records = fix_frame_records_filenames(inspect.getinnerframes(etb, context))\n",
      "  File \"C:\\Users\\Familia\\anaconda3\\envs\\entornoGPU\\lib\\inspect.py\", line 1502, in getinnerframes\n",
      "    frameinfo = (tb.tb_frame,) + getframeinfo(tb, context)\n",
      "  File \"C:\\Users\\Familia\\anaconda3\\envs\\entornoGPU\\lib\\inspect.py\", line 1460, in getframeinfo\n",
      "    filename = getsourcefile(frame) or getfile(frame)\n",
      "  File \"C:\\Users\\Familia\\anaconda3\\envs\\entornoGPU\\lib\\inspect.py\", line 696, in getsourcefile\n",
      "    if getattr(getmodule(object, filename), '__loader__', None) is not None:\n",
      "  File \"C:\\Users\\Familia\\anaconda3\\envs\\entornoGPU\\lib\\inspect.py\", line 733, in getmodule\n",
      "    if ismodule(module) and hasattr(module, '__file__'):\n",
      "  File \"C:\\Users\\Familia\\anaconda3\\envs\\entornoGPU\\lib\\site-packages\\tensorflow\\__init__.py\", line 50, in __getattr__\n",
      "    module = self._load()\n",
      "  File \"C:\\Users\\Familia\\anaconda3\\envs\\entornoGPU\\lib\\site-packages\\tensorflow\\__init__.py\", line 44, in _load\n",
      "    module = _importlib.import_module(self.__name__)\n",
      "  File \"C:\\Users\\Familia\\anaconda3\\envs\\entornoGPU\\lib\\importlib\\__init__.py\", line 127, in import_module\n",
      "    return _bootstrap._gcd_import(name[level:], package, level)\n",
      "  File \"<frozen importlib._bootstrap>\", line 1006, in _gcd_import\n",
      "  File \"<frozen importlib._bootstrap>\", line 983, in _find_and_load\n",
      "  File \"<frozen importlib._bootstrap>\", line 965, in _find_and_load_unlocked\n",
      "ModuleNotFoundError: No module named 'tensorflow_core.estimator'\n"
     ]
    }
   ],
   "source": [
    "from tensorflow.keras.preprocessing.image import ImageDataGenerator\n",
    "from tensorflow.keras.models import Sequential\n",
    "from tensorflow.keras.layers import Conv2D, MaxPooling2D, Flatten, Dense, Dropout\n",
    "from tensorflow.keras.optimizers import Adam\n",
    "\n",
    "# Definir la ruta de la base de datos\n",
    "database_path = '../../database/105_classes_pins_dataset/'\n",
    "# Preprocesamiento de datos con ImageDataGenerator\n",
    "train_datagen = ImageDataGenerator(rescale=1./255,\n",
    "                                   shear_range=0.2,\n",
    "                                   zoom_range=0.2,\n",
    "                                   horizontal_flip=True,\n",
    "                                   validation_split=0.2)\n",
    "# Generadores de datos para entrenamiento y validación\n",
    "train_generator = train_datagen.flow_from_directory(\n",
    "    database_path,\n",
    "    target_size=(200, 200),  # Cambio al tamaño 50x50\n",
    "    batch_size=32,\n",
    "    class_mode='categorical',\n",
    "    subset='training')\n",
    "validation_generator = train_datagen.flow_from_directory(\n",
    "    database_path,\n",
    "    target_size=(200, 200),  # Cambio al tamaño 50x50\n",
    "    batch_size=32,\n",
    "    class_mode='categorical',\n",
    "    subset='validation')\n",
    "\n",
    "# Inicializar el modelo\n",
    "model = Sequential()\n",
    "# Agregar capas convolucionales y de pooling\n",
    "model.add(Conv2D(32, (3, 3), activation='relu', input_shape=(200, 200, 3)))  # Cambio a 50x50\n",
    "model.add(MaxPooling2D((2, 2)))\n",
    "\n",
    "# Agregar dos capas convolucionales adicionales\n",
    "model.add(Conv2D(128, (3, 3), activation='relu'))\n",
    "model.add(MaxPooling2D((2, 2)))\n",
    "model.add(Conv2D(128, (3, 3), activation='relu'))\n",
    "model.add(MaxPooling2D((2, 2)))\n",
    "\n",
    "# Modificar el tamaño de las capas densas (totalmente conectadas)\n",
    "model.add(Flatten())\n",
    "model.add(Dense(128, activation='relu'))\n",
    "model.add(Dropout(0.5))\n",
    "\n",
    "# Cambiar el número de clases si es necesario\n",
    "model.add(Dense(len(train_generator.class_indices), activation='softmax'))\n",
    "\n",
    "# Compilar el modelo\n",
    "model.compile(optimizer=Adam(learning_rate=0.001),\n",
    "              loss='categorical_crossentropy',\n",
    "              metrics=['accuracy'])\n",
    "\n",
    "# Entrenar el modelo\n",
    "model.fit(train_generator,\n",
    "          steps_per_epoch=len(train_generator),\n",
    "          epochs=10,\n",
    "          validation_data=validation_generator,\n",
    "          validation_steps=len(validation_generator))\n"
   ]
  },
  {
   "cell_type": "code",
   "execution_count": null,
   "id": "ce0fec9f",
   "metadata": {},
   "outputs": [],
   "source": []
  },
  {
   "cell_type": "code",
   "execution_count": null,
   "id": "734b84d9",
   "metadata": {},
   "outputs": [],
   "source": []
  },
  {
   "cell_type": "code",
   "execution_count": null,
   "id": "e5065adf",
   "metadata": {},
   "outputs": [],
   "source": []
  },
  {
   "cell_type": "code",
   "execution_count": null,
   "id": "290c2d5b",
   "metadata": {},
   "outputs": [],
   "source": []
  },
  {
   "cell_type": "code",
   "execution_count": null,
   "id": "4565774f",
   "metadata": {},
   "outputs": [],
   "source": []
  },
  {
   "cell_type": "code",
   "execution_count": null,
   "id": "8a995a1b",
   "metadata": {},
   "outputs": [],
   "source": []
  },
  {
   "cell_type": "code",
   "execution_count": null,
   "id": "4f31ed71",
   "metadata": {},
   "outputs": [],
   "source": [
    "from keras.wrappers.scikit_learn import KerasClassifier\n",
    "from sklearn.model_selection import GridSearchCV\n",
    "from keras.models import Sequential\n",
    "from keras.layers import Conv2D, MaxPooling2D, Flatten, Dense, Dropout\n",
    "from keras.optimizers import Adam\n",
    "from keras.preprocessing.image import ImageDataGenerator"
   ]
  },
  {
   "cell_type": "code",
   "execution_count": null,
   "id": "d136d896",
   "metadata": {},
   "outputs": [],
   "source": [
    "# Función para crear el modelo\n",
    "def create_model(learning_rate=0.001, filters=32):\n",
    "    model = Sequential()\n",
    "    model.add(Conv2D(filters, (3, 3), activation='relu', input_shape=(224, 224, 3)))\n",
    "    model.add(MaxPooling2D((2, 2)))\n",
    "    model.add(Flatten())\n",
    "    model.add(Dense(128, activation='relu'))\n",
    "    model.add(Dropout(0.5))\n",
    "    model.add(Dense(len(train_generator.class_indices), activation='softmax'))\n",
    "\n",
    "    model.compile(optimizer=Adam(learning_rate=learning_rate),\n",
    "                  loss='categorical_crossentropy',\n",
    "                  metrics=['accuracy'])\n",
    "    \n",
    "    return model\n"
   ]
  },
  {
   "cell_type": "code",
   "execution_count": null,
   "id": "48a05bb2",
   "metadata": {},
   "outputs": [],
   "source": [
    "# Definir la ruta de la base de datos y el generador de datos\n",
    "database_path = '../../database/105_classes_pins_dataset/'\n",
    "train_datagen = ImageDataGenerator(rescale=1./255,\n",
    "                                   shear_range=0.2,\n",
    "                                   zoom_range=0.2,\n",
    "                                   horizontal_flip=True,\n",
    "                                   validation_split=0.2)\n",
    "train_generator = train_datagen.flow_from_directory(\n",
    "    database_path,\n",
    "    target_size=(224, 224),\n",
    "    batch_size=1,\n",
    "    class_mode='categorical',\n",
    "    subset='training')"
   ]
  },
  {
   "cell_type": "code",
   "execution_count": null,
   "id": "3d0511aa",
   "metadata": {},
   "outputs": [],
   "source": [
    "# Crear el modelo\n",
    "model = KerasClassifier(build_fn=create_model, epochs=10, verbose=0)"
   ]
  },
  {
   "cell_type": "code",
   "execution_count": null,
   "id": "93c4531e",
   "metadata": {},
   "outputs": [],
   "source": [
    "# Definir los hiperparámetros a buscar\n",
    "param_grid = {\n",
    "    'learning_rate': [0.001, 0.01, 0.1],\n",
    "    'batch_size': [16, 32, 64],\n",
    "    'filters': [16, 32, 64]\n",
    "}"
   ]
  },
  {
   "cell_type": "code",
   "execution_count": null,
   "id": "a10fd2ab",
   "metadata": {},
   "outputs": [],
   "source": [
    "# Realizar la búsqueda en cuadrícula\n",
    "grid = GridSearchCV(estimator=model, param_grid=param_grid, cv=3)\n",
    "grid_result = grid.fit(train_generator)"
   ]
  },
  {
   "cell_type": "code",
   "execution_count": null,
   "id": "ac17be0e",
   "metadata": {},
   "outputs": [],
   "source": [
    "# Mostrar los resultados\n",
    "print(\"Mejor precisión obtenida:\", grid_result.best_score_)\n",
    "print(\"Con hiperparámetros:\", grid_result.best_params_)"
   ]
  },
  {
   "cell_type": "code",
   "execution_count": null,
   "id": "efc4a36d",
   "metadata": {},
   "outputs": [],
   "source": []
  }
 ],
 "metadata": {
  "kernelspec": {
   "display_name": "entornoGPU",
   "language": "python",
   "name": "entornogpu"
  },
  "language_info": {
   "codemirror_mode": {
    "name": "ipython",
    "version": 3
   },
   "file_extension": ".py",
   "mimetype": "text/x-python",
   "name": "python",
   "nbconvert_exporter": "python",
   "pygments_lexer": "ipython3",
   "version": "3.7.13"
  }
 },
 "nbformat": 4,
 "nbformat_minor": 5
}
